<?xml version="1.0" encoding="UTF-8"?>
<testng-results ignored="0" total="34" passed="15" failed="13" skipped="6">
  <reporter-output>
  </reporter-output>
  <suite started-at="2021-06-16T09:13:23Z" name="EmployeesRestAPISuite" finished-at="2021-06-16T09:13:45Z" duration-ms="22091">
    <groups>
    </groups>
    <test started-at="2021-06-16T09:13:23Z" name="EmployeesRestAPITest" finished-at="2021-06-16T09:13:45Z" duration-ms="22091">
      <class name="com.employeeapi.testCases.TC003_Post_Employee_Record">
        <test-method is-config="true" signature="setup()[pri:0, instance:com.employeeapi.testCases.TC003_Post_Employee_Record@68567e20]" started-at="2021-06-16T09:13:31Z" name="setup" finished-at="2021-06-16T09:13:31Z" duration-ms="4" status="PASS">
          <reporter-output>
          </reporter-output>
        </test-method> <!-- setup -->
        <test-method is-config="true" signature="createEmployee()[pri:0, instance:com.employeeapi.testCases.TC003_Post_Employee_Record@68567e20]" started-at="2021-06-16T09:13:31Z" name="createEmployee" finished-at="2021-06-16T09:13:38Z" duration-ms="6128" status="PASS">
          <reporter-output>
          </reporter-output>
        </test-method> <!-- createEmployee -->
        <test-method signature="checkContentType()[pri:0, instance:com.employeeapi.testCases.TC003_Post_Employee_Record@68567e20]" started-at="2021-06-16T09:13:38Z" name="checkContentType" finished-at="2021-06-16T09:13:38Z" duration-ms="2" status="PASS">
          <reporter-output>
          </reporter-output>
        </test-method> <!-- checkContentType -->
        <test-method signature="checkResposeBody()[pri:0, instance:com.employeeapi.testCases.TC003_Post_Employee_Record@68567e20]" started-at="2021-06-16T09:13:38Z" name="checkResposeBody" finished-at="2021-06-16T09:13:38Z" duration-ms="2" status="FAIL">
          <exception class="java.lang.AssertionError">
            <message>
              <![CDATA[expected [true] but found [false]]]>
            </message>
            <full-stacktrace>
              <![CDATA[java.lang.AssertionError: expected [true] but found [false]
at org.testng.Assert.fail(Assert.java:96)
at org.testng.Assert.failNotEquals(Assert.java:776)
at org.testng.Assert.assertEqualsImpl(Assert.java:137)
at org.testng.Assert.assertEquals(Assert.java:118)
at org.testng.Assert.assertEquals(Assert.java:568)
at org.testng.Assert.assertEquals(Assert.java:578)
at com.employeeapi.testCases.TC003_Post_Employee_Record.checkResposeBody(TC003_Post_Employee_Record.java:71)
at java.base/jdk.internal.reflect.NativeMethodAccessorImpl.invoke0(Native Method)
at java.base/jdk.internal.reflect.NativeMethodAccessorImpl.invoke(NativeMethodAccessorImpl.java:64)
at java.base/jdk.internal.reflect.DelegatingMethodAccessorImpl.invoke(DelegatingMethodAccessorImpl.java:43)
at java.base/java.lang.reflect.Method.invoke(Method.java:564)
at org.testng.internal.MethodInvocationHelper.invokeMethod(MethodInvocationHelper.java:124)
at org.testng.internal.Invoker.invokeMethod(Invoker.java:583)
at org.testng.internal.Invoker.invokeTestMethod(Invoker.java:719)
at org.testng.internal.Invoker.invokeTestMethods(Invoker.java:989)
at org.testng.internal.TestMethodWorker.invokeTestMethods(TestMethodWorker.java:125)
at org.testng.internal.TestMethodWorker.run(TestMethodWorker.java:109)
at org.testng.TestRunner.privateRun(TestRunner.java:648)
at org.testng.TestRunner.run(TestRunner.java:505)
at org.testng.SuiteRunner.runTest(SuiteRunner.java:455)
at org.testng.SuiteRunner.runSequentially(SuiteRunner.java:450)
at org.testng.SuiteRunner.privateRun(SuiteRunner.java:415)
at org.testng.SuiteRunner.run(SuiteRunner.java:364)
at org.testng.SuiteRunnerWorker.runSuite(SuiteRunnerWorker.java:52)
at org.testng.SuiteRunnerWorker.run(SuiteRunnerWorker.java:84)
at org.testng.TestNG.runSuitesSequentially(TestNG.java:1208)
at org.testng.TestNG.runSuitesLocally(TestNG.java:1137)
at org.testng.TestNG.runSuites(TestNG.java:1049)
at org.testng.TestNG.run(TestNG.java:1017)
at org.testng.remote.AbstractRemoteTestNG.run(AbstractRemoteTestNG.java:115)
at org.testng.remote.RemoteTestNG.initAndRun(RemoteTestNG.java:251)
at org.testng.remote.RemoteTestNG.main(RemoteTestNG.java:77)
]]>
            </full-stacktrace>
          </exception> <!-- java.lang.AssertionError -->
          <reporter-output>
          </reporter-output>
        </test-method> <!-- checkResposeBody -->
        <test-method signature="checkStatusCode()[pri:0, instance:com.employeeapi.testCases.TC003_Post_Employee_Record@68567e20]" started-at="2021-06-16T09:13:38Z" name="checkStatusCode" finished-at="2021-06-16T09:13:38Z" duration-ms="1" status="FAIL">
          <exception class="java.lang.AssertionError">
            <message>
              <![CDATA[expected [200] but found [429]]]>
            </message>
            <full-stacktrace>
              <![CDATA[java.lang.AssertionError: expected [200] but found [429]
at org.testng.Assert.fail(Assert.java:96)
at org.testng.Assert.failNotEquals(Assert.java:776)
at org.testng.Assert.assertEqualsImpl(Assert.java:137)
at org.testng.Assert.assertEquals(Assert.java:118)
at org.testng.Assert.assertEquals(Assert.java:652)
at org.testng.Assert.assertEquals(Assert.java:662)
at com.employeeapi.testCases.TC003_Post_Employee_Record.checkStatusCode(TC003_Post_Employee_Record.java:80)
at java.base/jdk.internal.reflect.NativeMethodAccessorImpl.invoke0(Native Method)
at java.base/jdk.internal.reflect.NativeMethodAccessorImpl.invoke(NativeMethodAccessorImpl.java:64)
at java.base/jdk.internal.reflect.DelegatingMethodAccessorImpl.invoke(DelegatingMethodAccessorImpl.java:43)
at java.base/java.lang.reflect.Method.invoke(Method.java:564)
at org.testng.internal.MethodInvocationHelper.invokeMethod(MethodInvocationHelper.java:124)
at org.testng.internal.Invoker.invokeMethod(Invoker.java:583)
at org.testng.internal.Invoker.invokeTestMethod(Invoker.java:719)
at org.testng.internal.Invoker.invokeTestMethods(Invoker.java:989)
at org.testng.internal.TestMethodWorker.invokeTestMethods(TestMethodWorker.java:125)
at org.testng.internal.TestMethodWorker.run(TestMethodWorker.java:109)
at org.testng.TestRunner.privateRun(TestRunner.java:648)
at org.testng.TestRunner.run(TestRunner.java:505)
at org.testng.SuiteRunner.runTest(SuiteRunner.java:455)
at org.testng.SuiteRunner.runSequentially(SuiteRunner.java:450)
at org.testng.SuiteRunner.privateRun(SuiteRunner.java:415)
at org.testng.SuiteRunner.run(SuiteRunner.java:364)
at org.testng.SuiteRunnerWorker.runSuite(SuiteRunnerWorker.java:52)
at org.testng.SuiteRunnerWorker.run(SuiteRunnerWorker.java:84)
at org.testng.TestNG.runSuitesSequentially(TestNG.java:1208)
at org.testng.TestNG.runSuitesLocally(TestNG.java:1137)
at org.testng.TestNG.runSuites(TestNG.java:1049)
at org.testng.TestNG.run(TestNG.java:1017)
at org.testng.remote.AbstractRemoteTestNG.run(AbstractRemoteTestNG.java:115)
at org.testng.remote.RemoteTestNG.initAndRun(RemoteTestNG.java:251)
at org.testng.remote.RemoteTestNG.main(RemoteTestNG.java:77)
]]>
            </full-stacktrace>
          </exception> <!-- java.lang.AssertionError -->
          <reporter-output>
          </reporter-output>
        </test-method> <!-- checkStatusCode -->
        <test-method signature="checkcontentEncoding()[pri:0, instance:com.employeeapi.testCases.TC003_Post_Employee_Record@68567e20]" started-at="2021-06-16T09:13:38Z" name="checkcontentEncoding" finished-at="2021-06-16T09:13:38Z" duration-ms="1" status="FAIL">
          <exception class="java.lang.AssertionError">
            <message>
              <![CDATA[expected [gzip] but found [null]]]>
            </message>
            <full-stacktrace>
              <![CDATA[java.lang.AssertionError: expected [gzip] but found [null]
at org.testng.Assert.fail(Assert.java:96)
at org.testng.Assert.failNotEquals(Assert.java:776)
at org.testng.Assert.assertEqualsImpl(Assert.java:132)
at org.testng.Assert.assertEquals(Assert.java:118)
at org.testng.Assert.assertEquals(Assert.java:453)
at org.testng.Assert.assertEquals(Assert.java:463)
at com.employeeapi.testCases.TC003_Post_Employee_Record.checkcontentEncoding(TC003_Post_Employee_Record.java:109)
at java.base/jdk.internal.reflect.NativeMethodAccessorImpl.invoke0(Native Method)
at java.base/jdk.internal.reflect.NativeMethodAccessorImpl.invoke(NativeMethodAccessorImpl.java:64)
at java.base/jdk.internal.reflect.DelegatingMethodAccessorImpl.invoke(DelegatingMethodAccessorImpl.java:43)
at java.base/java.lang.reflect.Method.invoke(Method.java:564)
at org.testng.internal.MethodInvocationHelper.invokeMethod(MethodInvocationHelper.java:124)
at org.testng.internal.Invoker.invokeMethod(Invoker.java:583)
at org.testng.internal.Invoker.invokeTestMethod(Invoker.java:719)
at org.testng.internal.Invoker.invokeTestMethods(Invoker.java:989)
at org.testng.internal.TestMethodWorker.invokeTestMethods(TestMethodWorker.java:125)
at org.testng.internal.TestMethodWorker.run(TestMethodWorker.java:109)
at org.testng.TestRunner.privateRun(TestRunner.java:648)
at org.testng.TestRunner.run(TestRunner.java:505)
at org.testng.SuiteRunner.runTest(SuiteRunner.java:455)
at org.testng.SuiteRunner.runSequentially(SuiteRunner.java:450)
at org.testng.SuiteRunner.privateRun(SuiteRunner.java:415)
at org.testng.SuiteRunner.run(SuiteRunner.java:364)
at org.testng.SuiteRunnerWorker.runSuite(SuiteRunnerWorker.java:52)
at org.testng.SuiteRunnerWorker.run(SuiteRunnerWorker.java:84)
at org.testng.TestNG.runSuitesSequentially(TestNG.java:1208)
at org.testng.TestNG.runSuitesLocally(TestNG.java:1137)
at org.testng.TestNG.runSuites(TestNG.java:1049)
at org.testng.TestNG.run(TestNG.java:1017)
at org.testng.remote.AbstractRemoteTestNG.run(AbstractRemoteTestNG.java:115)
at org.testng.remote.RemoteTestNG.initAndRun(RemoteTestNG.java:251)
at org.testng.remote.RemoteTestNG.main(RemoteTestNG.java:77)
]]>
            </full-stacktrace>
          </exception> <!-- java.lang.AssertionError -->
          <reporter-output>
          </reporter-output>
        </test-method> <!-- checkcontentEncoding -->
        <test-method signature="checkserverType()[pri:0, instance:com.employeeapi.testCases.TC003_Post_Employee_Record@68567e20]" started-at="2021-06-16T09:13:38Z" name="checkserverType" finished-at="2021-06-16T09:13:38Z" duration-ms="1" status="FAIL">
          <exception class="java.lang.AssertionError">
            <message>
              <![CDATA[expected [nginx/1.14.1] but found [cloudflare]]]>
            </message>
            <full-stacktrace>
              <![CDATA[java.lang.AssertionError: expected [nginx/1.14.1] but found [cloudflare]
at org.testng.Assert.fail(Assert.java:96)
at org.testng.Assert.failNotEquals(Assert.java:776)
at org.testng.Assert.assertEqualsImpl(Assert.java:137)
at org.testng.Assert.assertEquals(Assert.java:118)
at org.testng.Assert.assertEquals(Assert.java:453)
at org.testng.Assert.assertEquals(Assert.java:463)
at com.employeeapi.testCases.TC003_Post_Employee_Record.checkserverType(TC003_Post_Employee_Record.java:102)
at java.base/jdk.internal.reflect.NativeMethodAccessorImpl.invoke0(Native Method)
at java.base/jdk.internal.reflect.NativeMethodAccessorImpl.invoke(NativeMethodAccessorImpl.java:64)
at java.base/jdk.internal.reflect.DelegatingMethodAccessorImpl.invoke(DelegatingMethodAccessorImpl.java:43)
at java.base/java.lang.reflect.Method.invoke(Method.java:564)
at org.testng.internal.MethodInvocationHelper.invokeMethod(MethodInvocationHelper.java:124)
at org.testng.internal.Invoker.invokeMethod(Invoker.java:583)
at org.testng.internal.Invoker.invokeTestMethod(Invoker.java:719)
at org.testng.internal.Invoker.invokeTestMethods(Invoker.java:989)
at org.testng.internal.TestMethodWorker.invokeTestMethods(TestMethodWorker.java:125)
at org.testng.internal.TestMethodWorker.run(TestMethodWorker.java:109)
at org.testng.TestRunner.privateRun(TestRunner.java:648)
at org.testng.TestRunner.run(TestRunner.java:505)
at org.testng.SuiteRunner.runTest(SuiteRunner.java:455)
at org.testng.SuiteRunner.runSequentially(SuiteRunner.java:450)
at org.testng.SuiteRunner.privateRun(SuiteRunner.java:415)
at org.testng.SuiteRunner.run(SuiteRunner.java:364)
at org.testng.SuiteRunnerWorker.runSuite(SuiteRunnerWorker.java:52)
at org.testng.SuiteRunnerWorker.run(SuiteRunnerWorker.java:84)
at org.testng.TestNG.runSuitesSequentially(TestNG.java:1208)
at org.testng.TestNG.runSuitesLocally(TestNG.java:1137)
at org.testng.TestNG.runSuites(TestNG.java:1049)
at org.testng.TestNG.run(TestNG.java:1017)
at org.testng.remote.AbstractRemoteTestNG.run(AbstractRemoteTestNG.java:115)
at org.testng.remote.RemoteTestNG.initAndRun(RemoteTestNG.java:251)
at org.testng.remote.RemoteTestNG.main(RemoteTestNG.java:77)
]]>
            </full-stacktrace>
          </exception> <!-- java.lang.AssertionError -->
          <reporter-output>
          </reporter-output>
        </test-method> <!-- checkserverType -->
        <test-method signature="checkstatusLine()[pri:0, instance:com.employeeapi.testCases.TC003_Post_Employee_Record@68567e20]" started-at="2021-06-16T09:13:38Z" name="checkstatusLine" finished-at="2021-06-16T09:13:38Z" duration-ms="0" status="FAIL">
          <exception class="java.lang.AssertionError">
            <message>
              <![CDATA[expected [HTTP/1.1 200 OK] but found [HTTP/1.1 429 Too Many Requests]]]>
            </message>
            <full-stacktrace>
              <![CDATA[java.lang.AssertionError: expected [HTTP/1.1 200 OK] but found [HTTP/1.1 429 Too Many Requests]
at org.testng.Assert.fail(Assert.java:96)
at org.testng.Assert.failNotEquals(Assert.java:776)
at org.testng.Assert.assertEqualsImpl(Assert.java:137)
at org.testng.Assert.assertEquals(Assert.java:118)
at org.testng.Assert.assertEquals(Assert.java:453)
at org.testng.Assert.assertEquals(Assert.java:463)
at com.employeeapi.testCases.TC003_Post_Employee_Record.checkstatusLine(TC003_Post_Employee_Record.java:87)
at java.base/jdk.internal.reflect.NativeMethodAccessorImpl.invoke0(Native Method)
at java.base/jdk.internal.reflect.NativeMethodAccessorImpl.invoke(NativeMethodAccessorImpl.java:64)
at java.base/jdk.internal.reflect.DelegatingMethodAccessorImpl.invoke(DelegatingMethodAccessorImpl.java:43)
at java.base/java.lang.reflect.Method.invoke(Method.java:564)
at org.testng.internal.MethodInvocationHelper.invokeMethod(MethodInvocationHelper.java:124)
at org.testng.internal.Invoker.invokeMethod(Invoker.java:583)
at org.testng.internal.Invoker.invokeTestMethod(Invoker.java:719)
at org.testng.internal.Invoker.invokeTestMethods(Invoker.java:989)
at org.testng.internal.TestMethodWorker.invokeTestMethods(TestMethodWorker.java:125)
at org.testng.internal.TestMethodWorker.run(TestMethodWorker.java:109)
at org.testng.TestRunner.privateRun(TestRunner.java:648)
at org.testng.TestRunner.run(TestRunner.java:505)
at org.testng.SuiteRunner.runTest(SuiteRunner.java:455)
at org.testng.SuiteRunner.runSequentially(SuiteRunner.java:450)
at org.testng.SuiteRunner.privateRun(SuiteRunner.java:415)
at org.testng.SuiteRunner.run(SuiteRunner.java:364)
at org.testng.SuiteRunnerWorker.runSuite(SuiteRunnerWorker.java:52)
at org.testng.SuiteRunnerWorker.run(SuiteRunnerWorker.java:84)
at org.testng.TestNG.runSuitesSequentially(TestNG.java:1208)
at org.testng.TestNG.runSuitesLocally(TestNG.java:1137)
at org.testng.TestNG.runSuites(TestNG.java:1049)
at org.testng.TestNG.run(TestNG.java:1017)
at org.testng.remote.AbstractRemoteTestNG.run(AbstractRemoteTestNG.java:115)
at org.testng.remote.RemoteTestNG.initAndRun(RemoteTestNG.java:251)
at org.testng.remote.RemoteTestNG.main(RemoteTestNG.java:77)
]]>
            </full-stacktrace>
          </exception> <!-- java.lang.AssertionError -->
          <reporter-output>
          </reporter-output>
        </test-method> <!-- checkstatusLine -->
        <test-method is-config="true" signature="tearDown()[pri:0, instance:com.employeeapi.testCases.TC003_Post_Employee_Record@68567e20]" started-at="2021-06-16T09:13:38Z" name="tearDown" finished-at="2021-06-16T09:13:38Z" duration-ms="1" status="PASS">
          <reporter-output>
          </reporter-output>
        </test-method> <!-- tearDown -->
      </class> <!-- com.employeeapi.testCases.TC003_Post_Employee_Record -->
      <class name="com.employeeapi.testCases.TC005_Delete_Employee_Record">
        <test-method is-config="true" signature="setup()[pri:0, instance:com.employeeapi.testCases.TC005_Delete_Employee_Record@11fc564b]" started-at="2021-06-16T09:13:44Z" name="setup" finished-at="2021-06-16T09:13:44Z" duration-ms="2" status="PASS">
          <reporter-output>
          </reporter-output>
        </test-method> <!-- setup -->
        <test-method is-config="true" signature="deleteEmployee()[pri:0, instance:com.employeeapi.testCases.TC005_Delete_Employee_Record@11fc564b]" started-at="2021-06-16T09:13:44Z" name="deleteEmployee" finished-at="2021-06-16T09:13:45Z" duration-ms="1056" status="FAIL">
          <exception class="io.restassured.path.json.exception.JsonPathException">
            <message>
              <![CDATA[Failed to parse the JSON document]]>
            </message>
            <full-stacktrace>
              <![CDATA[io.restassured.path.json.exception.JsonPathException: Failed to parse the JSON document
at io.restassured.path.json.JsonPath$ExceptionCatcher.invoke(JsonPath.java:930)
at io.restassured.path.json.JsonPath$4.doParseWith(JsonPath.java:895)
at io.restassured.path.json.JsonPath$JsonParser.parseWith(JsonPath.java:975)
at io.restassured.path.json.JsonPath.get(JsonPath.java:201)
at com.employeeapi.testCases.TC005_Delete_Employee_Record.deleteEmployee(TC005_Delete_Employee_Record.java:49)
at java.base/jdk.internal.reflect.NativeMethodAccessorImpl.invoke0(Native Method)
at java.base/jdk.internal.reflect.NativeMethodAccessorImpl.invoke(NativeMethodAccessorImpl.java:64)
at java.base/jdk.internal.reflect.DelegatingMethodAccessorImpl.invoke(DelegatingMethodAccessorImpl.java:43)
at java.base/java.lang.reflect.Method.invoke(Method.java:564)
at org.testng.internal.MethodInvocationHelper.invokeMethod(MethodInvocationHelper.java:124)
at org.testng.internal.MethodInvocationHelper.invokeMethodConsideringTimeout(MethodInvocationHelper.java:59)
at org.testng.internal.Invoker.invokeConfigurationMethod(Invoker.java:458)
at org.testng.internal.Invoker.invokeConfigurations(Invoker.java:222)
at org.testng.internal.Invoker.invokeConfigurations(Invoker.java:142)
at org.testng.internal.TestMethodWorker.invokeBeforeClassMethods(TestMethodWorker.java:168)
at org.testng.internal.TestMethodWorker.run(TestMethodWorker.java:105)
at org.testng.TestRunner.privateRun(TestRunner.java:648)
at org.testng.TestRunner.run(TestRunner.java:505)
at org.testng.SuiteRunner.runTest(SuiteRunner.java:455)
at org.testng.SuiteRunner.runSequentially(SuiteRunner.java:450)
at org.testng.SuiteRunner.privateRun(SuiteRunner.java:415)
at org.testng.SuiteRunner.run(SuiteRunner.java:364)
at org.testng.SuiteRunnerWorker.runSuite(SuiteRunnerWorker.java:52)
at org.testng.SuiteRunnerWorker.run(SuiteRunnerWorker.java:84)
at org.testng.TestNG.runSuitesSequentially(TestNG.java:1208)
at org.testng.TestNG.runSuitesLocally(TestNG.java:1137)
at org.testng.TestNG.runSuites(TestNG.java:1049)
at org.testng.TestNG.run(TestNG.java:1017)
at org.testng.remote.AbstractRemoteTestNG.run(AbstractRemoteTestNG.java:115)
at org.testng.remote.RemoteTestNG.initAndRun(RemoteTestNG.java:251)
at org.testng.remote.RemoteTestNG.main(RemoteTestNG.java:77)
Caused by: groovy.json.JsonException: Lexing failed on line: 1, column: 1, while reading '<', no possible valid JSON value or punctuation could be recognized.
at groovy.json.JsonLexer.nextToken(JsonLexer.java:83)
at groovy.json.JsonLexer$nextToken.call(Unknown Source)
at org.codehaus.groovy.runtime.callsite.CallSiteArray.defaultCall(CallSiteArray.java:48)
at org.codehaus.groovy.runtime.callsite.AbstractCallSite.call(AbstractCallSite.java:113)
at org.codehaus.groovy.runtime.callsite.AbstractCallSite.call(AbstractCallSite.java:117)
at io.restassured.internal.path.json.ConfigurableJsonSlurper.parse(ConfigurableJsonSlurper.groovy:97)
at io.restassured.internal.path.json.ConfigurableJsonSlurper$parse.callCurrent(Unknown Source)
at org.codehaus.groovy.runtime.callsite.CallSiteArray.defaultCallCurrent(CallSiteArray.java:52)
at org.codehaus.groovy.runtime.callsite.AbstractCallSite.callCurrent(AbstractCallSite.java:154)
at org.codehaus.groovy.runtime.callsite.AbstractCallSite.callCurrent(AbstractCallSite.java:166)
at io.restassured.internal.path.json.ConfigurableJsonSlurper.parseText(ConfigurableJsonSlurper.groovy:83)
at io.restassured.path.json.JsonPath$4$1.method(JsonPath.java:893)
at io.restassured.path.json.JsonPath$ExceptionCatcher.invoke(JsonPath.java:928)
... 30 more
]]>
            </full-stacktrace>
          </exception> <!-- io.restassured.path.json.exception.JsonPathException -->
          <reporter-output>
          </reporter-output>
        </test-method> <!-- deleteEmployee -->
        <test-method signature="checkContentType()[pri:0, instance:com.employeeapi.testCases.TC005_Delete_Employee_Record@11fc564b]" started-at="2021-06-16T09:13:45Z" name="checkContentType" finished-at="2021-06-16T09:13:45Z" duration-ms="0" status="SKIP">
          <exception class="io.restassured.path.json.exception.JsonPathException">
            <message>
              <![CDATA[Failed to parse the JSON document]]>
            </message>
            <full-stacktrace>
              <![CDATA[io.restassured.path.json.exception.JsonPathException: Failed to parse the JSON document
at io.restassured.path.json.JsonPath$ExceptionCatcher.invoke(JsonPath.java:930)
at io.restassured.path.json.JsonPath$4.doParseWith(JsonPath.java:895)
at io.restassured.path.json.JsonPath$JsonParser.parseWith(JsonPath.java:975)
at io.restassured.path.json.JsonPath.get(JsonPath.java:201)
at com.employeeapi.testCases.TC005_Delete_Employee_Record.deleteEmployee(TC005_Delete_Employee_Record.java:49)
at java.base/jdk.internal.reflect.NativeMethodAccessorImpl.invoke0(Native Method)
at java.base/jdk.internal.reflect.NativeMethodAccessorImpl.invoke(NativeMethodAccessorImpl.java:64)
at java.base/jdk.internal.reflect.DelegatingMethodAccessorImpl.invoke(DelegatingMethodAccessorImpl.java:43)
at java.base/java.lang.reflect.Method.invoke(Method.java:564)
at org.testng.internal.MethodInvocationHelper.invokeMethod(MethodInvocationHelper.java:124)
at org.testng.internal.MethodInvocationHelper.invokeMethodConsideringTimeout(MethodInvocationHelper.java:59)
at org.testng.internal.Invoker.invokeConfigurationMethod(Invoker.java:458)
at org.testng.internal.Invoker.invokeConfigurations(Invoker.java:222)
at org.testng.internal.Invoker.invokeConfigurations(Invoker.java:142)
at org.testng.internal.TestMethodWorker.invokeBeforeClassMethods(TestMethodWorker.java:168)
at org.testng.internal.TestMethodWorker.run(TestMethodWorker.java:105)
at org.testng.TestRunner.privateRun(TestRunner.java:648)
at org.testng.TestRunner.run(TestRunner.java:505)
at org.testng.SuiteRunner.runTest(SuiteRunner.java:455)
at org.testng.SuiteRunner.runSequentially(SuiteRunner.java:450)
at org.testng.SuiteRunner.privateRun(SuiteRunner.java:415)
at org.testng.SuiteRunner.run(SuiteRunner.java:364)
at org.testng.SuiteRunnerWorker.runSuite(SuiteRunnerWorker.java:52)
at org.testng.SuiteRunnerWorker.run(SuiteRunnerWorker.java:84)
at org.testng.TestNG.runSuitesSequentially(TestNG.java:1208)
at org.testng.TestNG.runSuitesLocally(TestNG.java:1137)
at org.testng.TestNG.runSuites(TestNG.java:1049)
at org.testng.TestNG.run(TestNG.java:1017)
at org.testng.remote.AbstractRemoteTestNG.run(AbstractRemoteTestNG.java:115)
at org.testng.remote.RemoteTestNG.initAndRun(RemoteTestNG.java:251)
at org.testng.remote.RemoteTestNG.main(RemoteTestNG.java:77)
Caused by: groovy.json.JsonException: Lexing failed on line: 1, column: 1, while reading '<', no possible valid JSON value or punctuation could be recognized.
at groovy.json.JsonLexer.nextToken(JsonLexer.java:83)
at groovy.json.JsonLexer$nextToken.call(Unknown Source)
at org.codehaus.groovy.runtime.callsite.CallSiteArray.defaultCall(CallSiteArray.java:48)
at org.codehaus.groovy.runtime.callsite.AbstractCallSite.call(AbstractCallSite.java:113)
at org.codehaus.groovy.runtime.callsite.AbstractCallSite.call(AbstractCallSite.java:117)
at io.restassured.internal.path.json.ConfigurableJsonSlurper.parse(ConfigurableJsonSlurper.groovy:97)
at io.restassured.internal.path.json.ConfigurableJsonSlurper$parse.callCurrent(Unknown Source)
at org.codehaus.groovy.runtime.callsite.CallSiteArray.defaultCallCurrent(CallSiteArray.java:52)
at org.codehaus.groovy.runtime.callsite.AbstractCallSite.callCurrent(AbstractCallSite.java:154)
at org.codehaus.groovy.runtime.callsite.AbstractCallSite.callCurrent(AbstractCallSite.java:166)
at io.restassured.internal.path.json.ConfigurableJsonSlurper.parseText(ConfigurableJsonSlurper.groovy:83)
at io.restassured.path.json.JsonPath$4$1.method(JsonPath.java:893)
at io.restassured.path.json.JsonPath$ExceptionCatcher.invoke(JsonPath.java:928)
... 30 more
]]>
            </full-stacktrace>
          </exception> <!-- io.restassured.path.json.exception.JsonPathException -->
          <reporter-output>
          </reporter-output>
        </test-method> <!-- checkContentType -->
        <test-method signature="checkResposeBody()[pri:0, instance:com.employeeapi.testCases.TC005_Delete_Employee_Record@11fc564b]" started-at="2021-06-16T09:13:45Z" name="checkResposeBody" finished-at="2021-06-16T09:13:45Z" duration-ms="0" status="SKIP">
          <exception class="io.restassured.path.json.exception.JsonPathException">
            <message>
              <![CDATA[Failed to parse the JSON document]]>
            </message>
            <full-stacktrace>
              <![CDATA[io.restassured.path.json.exception.JsonPathException: Failed to parse the JSON document
at io.restassured.path.json.JsonPath$ExceptionCatcher.invoke(JsonPath.java:930)
at io.restassured.path.json.JsonPath$4.doParseWith(JsonPath.java:895)
at io.restassured.path.json.JsonPath$JsonParser.parseWith(JsonPath.java:975)
at io.restassured.path.json.JsonPath.get(JsonPath.java:201)
at com.employeeapi.testCases.TC005_Delete_Employee_Record.deleteEmployee(TC005_Delete_Employee_Record.java:49)
at java.base/jdk.internal.reflect.NativeMethodAccessorImpl.invoke0(Native Method)
at java.base/jdk.internal.reflect.NativeMethodAccessorImpl.invoke(NativeMethodAccessorImpl.java:64)
at java.base/jdk.internal.reflect.DelegatingMethodAccessorImpl.invoke(DelegatingMethodAccessorImpl.java:43)
at java.base/java.lang.reflect.Method.invoke(Method.java:564)
at org.testng.internal.MethodInvocationHelper.invokeMethod(MethodInvocationHelper.java:124)
at org.testng.internal.MethodInvocationHelper.invokeMethodConsideringTimeout(MethodInvocationHelper.java:59)
at org.testng.internal.Invoker.invokeConfigurationMethod(Invoker.java:458)
at org.testng.internal.Invoker.invokeConfigurations(Invoker.java:222)
at org.testng.internal.Invoker.invokeConfigurations(Invoker.java:142)
at org.testng.internal.TestMethodWorker.invokeBeforeClassMethods(TestMethodWorker.java:168)
at org.testng.internal.TestMethodWorker.run(TestMethodWorker.java:105)
at org.testng.TestRunner.privateRun(TestRunner.java:648)
at org.testng.TestRunner.run(TestRunner.java:505)
at org.testng.SuiteRunner.runTest(SuiteRunner.java:455)
at org.testng.SuiteRunner.runSequentially(SuiteRunner.java:450)
at org.testng.SuiteRunner.privateRun(SuiteRunner.java:415)
at org.testng.SuiteRunner.run(SuiteRunner.java:364)
at org.testng.SuiteRunnerWorker.runSuite(SuiteRunnerWorker.java:52)
at org.testng.SuiteRunnerWorker.run(SuiteRunnerWorker.java:84)
at org.testng.TestNG.runSuitesSequentially(TestNG.java:1208)
at org.testng.TestNG.runSuitesLocally(TestNG.java:1137)
at org.testng.TestNG.runSuites(TestNG.java:1049)
at org.testng.TestNG.run(TestNG.java:1017)
at org.testng.remote.AbstractRemoteTestNG.run(AbstractRemoteTestNG.java:115)
at org.testng.remote.RemoteTestNG.initAndRun(RemoteTestNG.java:251)
at org.testng.remote.RemoteTestNG.main(RemoteTestNG.java:77)
Caused by: groovy.json.JsonException: Lexing failed on line: 1, column: 1, while reading '<', no possible valid JSON value or punctuation could be recognized.
at groovy.json.JsonLexer.nextToken(JsonLexer.java:83)
at groovy.json.JsonLexer$nextToken.call(Unknown Source)
at org.codehaus.groovy.runtime.callsite.CallSiteArray.defaultCall(CallSiteArray.java:48)
at org.codehaus.groovy.runtime.callsite.AbstractCallSite.call(AbstractCallSite.java:113)
at org.codehaus.groovy.runtime.callsite.AbstractCallSite.call(AbstractCallSite.java:117)
at io.restassured.internal.path.json.ConfigurableJsonSlurper.parse(ConfigurableJsonSlurper.groovy:97)
at io.restassured.internal.path.json.ConfigurableJsonSlurper$parse.callCurrent(Unknown Source)
at org.codehaus.groovy.runtime.callsite.CallSiteArray.defaultCallCurrent(CallSiteArray.java:52)
at org.codehaus.groovy.runtime.callsite.AbstractCallSite.callCurrent(AbstractCallSite.java:154)
at org.codehaus.groovy.runtime.callsite.AbstractCallSite.callCurrent(AbstractCallSite.java:166)
at io.restassured.internal.path.json.ConfigurableJsonSlurper.parseText(ConfigurableJsonSlurper.groovy:83)
at io.restassured.path.json.JsonPath$4$1.method(JsonPath.java:893)
at io.restassured.path.json.JsonPath$ExceptionCatcher.invoke(JsonPath.java:928)
... 30 more
]]>
            </full-stacktrace>
          </exception> <!-- io.restassured.path.json.exception.JsonPathException -->
          <reporter-output>
          </reporter-output>
        </test-method> <!-- checkResposeBody -->
        <test-method signature="checkStatusCode()[pri:0, instance:com.employeeapi.testCases.TC005_Delete_Employee_Record@11fc564b]" started-at="2021-06-16T09:13:45Z" name="checkStatusCode" finished-at="2021-06-16T09:13:45Z" duration-ms="0" status="SKIP">
          <exception class="io.restassured.path.json.exception.JsonPathException">
            <message>
              <![CDATA[Failed to parse the JSON document]]>
            </message>
            <full-stacktrace>
              <![CDATA[io.restassured.path.json.exception.JsonPathException: Failed to parse the JSON document
at io.restassured.path.json.JsonPath$ExceptionCatcher.invoke(JsonPath.java:930)
at io.restassured.path.json.JsonPath$4.doParseWith(JsonPath.java:895)
at io.restassured.path.json.JsonPath$JsonParser.parseWith(JsonPath.java:975)
at io.restassured.path.json.JsonPath.get(JsonPath.java:201)
at com.employeeapi.testCases.TC005_Delete_Employee_Record.deleteEmployee(TC005_Delete_Employee_Record.java:49)
at java.base/jdk.internal.reflect.NativeMethodAccessorImpl.invoke0(Native Method)
at java.base/jdk.internal.reflect.NativeMethodAccessorImpl.invoke(NativeMethodAccessorImpl.java:64)
at java.base/jdk.internal.reflect.DelegatingMethodAccessorImpl.invoke(DelegatingMethodAccessorImpl.java:43)
at java.base/java.lang.reflect.Method.invoke(Method.java:564)
at org.testng.internal.MethodInvocationHelper.invokeMethod(MethodInvocationHelper.java:124)
at org.testng.internal.MethodInvocationHelper.invokeMethodConsideringTimeout(MethodInvocationHelper.java:59)
at org.testng.internal.Invoker.invokeConfigurationMethod(Invoker.java:458)
at org.testng.internal.Invoker.invokeConfigurations(Invoker.java:222)
at org.testng.internal.Invoker.invokeConfigurations(Invoker.java:142)
at org.testng.internal.TestMethodWorker.invokeBeforeClassMethods(TestMethodWorker.java:168)
at org.testng.internal.TestMethodWorker.run(TestMethodWorker.java:105)
at org.testng.TestRunner.privateRun(TestRunner.java:648)
at org.testng.TestRunner.run(TestRunner.java:505)
at org.testng.SuiteRunner.runTest(SuiteRunner.java:455)
at org.testng.SuiteRunner.runSequentially(SuiteRunner.java:450)
at org.testng.SuiteRunner.privateRun(SuiteRunner.java:415)
at org.testng.SuiteRunner.run(SuiteRunner.java:364)
at org.testng.SuiteRunnerWorker.runSuite(SuiteRunnerWorker.java:52)
at org.testng.SuiteRunnerWorker.run(SuiteRunnerWorker.java:84)
at org.testng.TestNG.runSuitesSequentially(TestNG.java:1208)
at org.testng.TestNG.runSuitesLocally(TestNG.java:1137)
at org.testng.TestNG.runSuites(TestNG.java:1049)
at org.testng.TestNG.run(TestNG.java:1017)
at org.testng.remote.AbstractRemoteTestNG.run(AbstractRemoteTestNG.java:115)
at org.testng.remote.RemoteTestNG.initAndRun(RemoteTestNG.java:251)
at org.testng.remote.RemoteTestNG.main(RemoteTestNG.java:77)
Caused by: groovy.json.JsonException: Lexing failed on line: 1, column: 1, while reading '<', no possible valid JSON value or punctuation could be recognized.
at groovy.json.JsonLexer.nextToken(JsonLexer.java:83)
at groovy.json.JsonLexer$nextToken.call(Unknown Source)
at org.codehaus.groovy.runtime.callsite.CallSiteArray.defaultCall(CallSiteArray.java:48)
at org.codehaus.groovy.runtime.callsite.AbstractCallSite.call(AbstractCallSite.java:113)
at org.codehaus.groovy.runtime.callsite.AbstractCallSite.call(AbstractCallSite.java:117)
at io.restassured.internal.path.json.ConfigurableJsonSlurper.parse(ConfigurableJsonSlurper.groovy:97)
at io.restassured.internal.path.json.ConfigurableJsonSlurper$parse.callCurrent(Unknown Source)
at org.codehaus.groovy.runtime.callsite.CallSiteArray.defaultCallCurrent(CallSiteArray.java:52)
at org.codehaus.groovy.runtime.callsite.AbstractCallSite.callCurrent(AbstractCallSite.java:154)
at org.codehaus.groovy.runtime.callsite.AbstractCallSite.callCurrent(AbstractCallSite.java:166)
at io.restassured.internal.path.json.ConfigurableJsonSlurper.parseText(ConfigurableJsonSlurper.groovy:83)
at io.restassured.path.json.JsonPath$4$1.method(JsonPath.java:893)
at io.restassured.path.json.JsonPath$ExceptionCatcher.invoke(JsonPath.java:928)
... 30 more
]]>
            </full-stacktrace>
          </exception> <!-- io.restassured.path.json.exception.JsonPathException -->
          <reporter-output>
          </reporter-output>
        </test-method> <!-- checkStatusCode -->
        <test-method signature="checkcontentEncoding()[pri:0, instance:com.employeeapi.testCases.TC005_Delete_Employee_Record@11fc564b]" started-at="2021-06-16T09:13:45Z" name="checkcontentEncoding" finished-at="2021-06-16T09:13:45Z" duration-ms="0" status="SKIP">
          <exception class="io.restassured.path.json.exception.JsonPathException">
            <message>
              <![CDATA[Failed to parse the JSON document]]>
            </message>
            <full-stacktrace>
              <![CDATA[io.restassured.path.json.exception.JsonPathException: Failed to parse the JSON document
at io.restassured.path.json.JsonPath$ExceptionCatcher.invoke(JsonPath.java:930)
at io.restassured.path.json.JsonPath$4.doParseWith(JsonPath.java:895)
at io.restassured.path.json.JsonPath$JsonParser.parseWith(JsonPath.java:975)
at io.restassured.path.json.JsonPath.get(JsonPath.java:201)
at com.employeeapi.testCases.TC005_Delete_Employee_Record.deleteEmployee(TC005_Delete_Employee_Record.java:49)
at java.base/jdk.internal.reflect.NativeMethodAccessorImpl.invoke0(Native Method)
at java.base/jdk.internal.reflect.NativeMethodAccessorImpl.invoke(NativeMethodAccessorImpl.java:64)
at java.base/jdk.internal.reflect.DelegatingMethodAccessorImpl.invoke(DelegatingMethodAccessorImpl.java:43)
at java.base/java.lang.reflect.Method.invoke(Method.java:564)
at org.testng.internal.MethodInvocationHelper.invokeMethod(MethodInvocationHelper.java:124)
at org.testng.internal.MethodInvocationHelper.invokeMethodConsideringTimeout(MethodInvocationHelper.java:59)
at org.testng.internal.Invoker.invokeConfigurationMethod(Invoker.java:458)
at org.testng.internal.Invoker.invokeConfigurations(Invoker.java:222)
at org.testng.internal.Invoker.invokeConfigurations(Invoker.java:142)
at org.testng.internal.TestMethodWorker.invokeBeforeClassMethods(TestMethodWorker.java:168)
at org.testng.internal.TestMethodWorker.run(TestMethodWorker.java:105)
at org.testng.TestRunner.privateRun(TestRunner.java:648)
at org.testng.TestRunner.run(TestRunner.java:505)
at org.testng.SuiteRunner.runTest(SuiteRunner.java:455)
at org.testng.SuiteRunner.runSequentially(SuiteRunner.java:450)
at org.testng.SuiteRunner.privateRun(SuiteRunner.java:415)
at org.testng.SuiteRunner.run(SuiteRunner.java:364)
at org.testng.SuiteRunnerWorker.runSuite(SuiteRunnerWorker.java:52)
at org.testng.SuiteRunnerWorker.run(SuiteRunnerWorker.java:84)
at org.testng.TestNG.runSuitesSequentially(TestNG.java:1208)
at org.testng.TestNG.runSuitesLocally(TestNG.java:1137)
at org.testng.TestNG.runSuites(TestNG.java:1049)
at org.testng.TestNG.run(TestNG.java:1017)
at org.testng.remote.AbstractRemoteTestNG.run(AbstractRemoteTestNG.java:115)
at org.testng.remote.RemoteTestNG.initAndRun(RemoteTestNG.java:251)
at org.testng.remote.RemoteTestNG.main(RemoteTestNG.java:77)
Caused by: groovy.json.JsonException: Lexing failed on line: 1, column: 1, while reading '<', no possible valid JSON value or punctuation could be recognized.
at groovy.json.JsonLexer.nextToken(JsonLexer.java:83)
at groovy.json.JsonLexer$nextToken.call(Unknown Source)
at org.codehaus.groovy.runtime.callsite.CallSiteArray.defaultCall(CallSiteArray.java:48)
at org.codehaus.groovy.runtime.callsite.AbstractCallSite.call(AbstractCallSite.java:113)
at org.codehaus.groovy.runtime.callsite.AbstractCallSite.call(AbstractCallSite.java:117)
at io.restassured.internal.path.json.ConfigurableJsonSlurper.parse(ConfigurableJsonSlurper.groovy:97)
at io.restassured.internal.path.json.ConfigurableJsonSlurper$parse.callCurrent(Unknown Source)
at org.codehaus.groovy.runtime.callsite.CallSiteArray.defaultCallCurrent(CallSiteArray.java:52)
at org.codehaus.groovy.runtime.callsite.AbstractCallSite.callCurrent(AbstractCallSite.java:154)
at org.codehaus.groovy.runtime.callsite.AbstractCallSite.callCurrent(AbstractCallSite.java:166)
at io.restassured.internal.path.json.ConfigurableJsonSlurper.parseText(ConfigurableJsonSlurper.groovy:83)
at io.restassured.path.json.JsonPath$4$1.method(JsonPath.java:893)
at io.restassured.path.json.JsonPath$ExceptionCatcher.invoke(JsonPath.java:928)
... 30 more
]]>
            </full-stacktrace>
          </exception> <!-- io.restassured.path.json.exception.JsonPathException -->
          <reporter-output>
          </reporter-output>
        </test-method> <!-- checkcontentEncoding -->
        <test-method signature="checkserverType()[pri:0, instance:com.employeeapi.testCases.TC005_Delete_Employee_Record@11fc564b]" started-at="2021-06-16T09:13:45Z" name="checkserverType" finished-at="2021-06-16T09:13:45Z" duration-ms="0" status="SKIP">
          <exception class="io.restassured.path.json.exception.JsonPathException">
            <message>
              <![CDATA[Failed to parse the JSON document]]>
            </message>
            <full-stacktrace>
              <![CDATA[io.restassured.path.json.exception.JsonPathException: Failed to parse the JSON document
at io.restassured.path.json.JsonPath$ExceptionCatcher.invoke(JsonPath.java:930)
at io.restassured.path.json.JsonPath$4.doParseWith(JsonPath.java:895)
at io.restassured.path.json.JsonPath$JsonParser.parseWith(JsonPath.java:975)
at io.restassured.path.json.JsonPath.get(JsonPath.java:201)
at com.employeeapi.testCases.TC005_Delete_Employee_Record.deleteEmployee(TC005_Delete_Employee_Record.java:49)
at java.base/jdk.internal.reflect.NativeMethodAccessorImpl.invoke0(Native Method)
at java.base/jdk.internal.reflect.NativeMethodAccessorImpl.invoke(NativeMethodAccessorImpl.java:64)
at java.base/jdk.internal.reflect.DelegatingMethodAccessorImpl.invoke(DelegatingMethodAccessorImpl.java:43)
at java.base/java.lang.reflect.Method.invoke(Method.java:564)
at org.testng.internal.MethodInvocationHelper.invokeMethod(MethodInvocationHelper.java:124)
at org.testng.internal.MethodInvocationHelper.invokeMethodConsideringTimeout(MethodInvocationHelper.java:59)
at org.testng.internal.Invoker.invokeConfigurationMethod(Invoker.java:458)
at org.testng.internal.Invoker.invokeConfigurations(Invoker.java:222)
at org.testng.internal.Invoker.invokeConfigurations(Invoker.java:142)
at org.testng.internal.TestMethodWorker.invokeBeforeClassMethods(TestMethodWorker.java:168)
at org.testng.internal.TestMethodWorker.run(TestMethodWorker.java:105)
at org.testng.TestRunner.privateRun(TestRunner.java:648)
at org.testng.TestRunner.run(TestRunner.java:505)
at org.testng.SuiteRunner.runTest(SuiteRunner.java:455)
at org.testng.SuiteRunner.runSequentially(SuiteRunner.java:450)
at org.testng.SuiteRunner.privateRun(SuiteRunner.java:415)
at org.testng.SuiteRunner.run(SuiteRunner.java:364)
at org.testng.SuiteRunnerWorker.runSuite(SuiteRunnerWorker.java:52)
at org.testng.SuiteRunnerWorker.run(SuiteRunnerWorker.java:84)
at org.testng.TestNG.runSuitesSequentially(TestNG.java:1208)
at org.testng.TestNG.runSuitesLocally(TestNG.java:1137)
at org.testng.TestNG.runSuites(TestNG.java:1049)
at org.testng.TestNG.run(TestNG.java:1017)
at org.testng.remote.AbstractRemoteTestNG.run(AbstractRemoteTestNG.java:115)
at org.testng.remote.RemoteTestNG.initAndRun(RemoteTestNG.java:251)
at org.testng.remote.RemoteTestNG.main(RemoteTestNG.java:77)
Caused by: groovy.json.JsonException: Lexing failed on line: 1, column: 1, while reading '<', no possible valid JSON value or punctuation could be recognized.
at groovy.json.JsonLexer.nextToken(JsonLexer.java:83)
at groovy.json.JsonLexer$nextToken.call(Unknown Source)
at org.codehaus.groovy.runtime.callsite.CallSiteArray.defaultCall(CallSiteArray.java:48)
at org.codehaus.groovy.runtime.callsite.AbstractCallSite.call(AbstractCallSite.java:113)
at org.codehaus.groovy.runtime.callsite.AbstractCallSite.call(AbstractCallSite.java:117)
at io.restassured.internal.path.json.ConfigurableJsonSlurper.parse(ConfigurableJsonSlurper.groovy:97)
at io.restassured.internal.path.json.ConfigurableJsonSlurper$parse.callCurrent(Unknown Source)
at org.codehaus.groovy.runtime.callsite.CallSiteArray.defaultCallCurrent(CallSiteArray.java:52)
at org.codehaus.groovy.runtime.callsite.AbstractCallSite.callCurrent(AbstractCallSite.java:154)
at org.codehaus.groovy.runtime.callsite.AbstractCallSite.callCurrent(AbstractCallSite.java:166)
at io.restassured.internal.path.json.ConfigurableJsonSlurper.parseText(ConfigurableJsonSlurper.groovy:83)
at io.restassured.path.json.JsonPath$4$1.method(JsonPath.java:893)
at io.restassured.path.json.JsonPath$ExceptionCatcher.invoke(JsonPath.java:928)
... 30 more
]]>
            </full-stacktrace>
          </exception> <!-- io.restassured.path.json.exception.JsonPathException -->
          <reporter-output>
          </reporter-output>
        </test-method> <!-- checkserverType -->
        <test-method signature="checkstatusLine()[pri:0, instance:com.employeeapi.testCases.TC005_Delete_Employee_Record@11fc564b]" started-at="2021-06-16T09:13:45Z" name="checkstatusLine" finished-at="2021-06-16T09:13:45Z" duration-ms="0" status="SKIP">
          <exception class="io.restassured.path.json.exception.JsonPathException">
            <message>
              <![CDATA[Failed to parse the JSON document]]>
            </message>
            <full-stacktrace>
              <![CDATA[io.restassured.path.json.exception.JsonPathException: Failed to parse the JSON document
at io.restassured.path.json.JsonPath$ExceptionCatcher.invoke(JsonPath.java:930)
at io.restassured.path.json.JsonPath$4.doParseWith(JsonPath.java:895)
at io.restassured.path.json.JsonPath$JsonParser.parseWith(JsonPath.java:975)
at io.restassured.path.json.JsonPath.get(JsonPath.java:201)
at com.employeeapi.testCases.TC005_Delete_Employee_Record.deleteEmployee(TC005_Delete_Employee_Record.java:49)
at java.base/jdk.internal.reflect.NativeMethodAccessorImpl.invoke0(Native Method)
at java.base/jdk.internal.reflect.NativeMethodAccessorImpl.invoke(NativeMethodAccessorImpl.java:64)
at java.base/jdk.internal.reflect.DelegatingMethodAccessorImpl.invoke(DelegatingMethodAccessorImpl.java:43)
at java.base/java.lang.reflect.Method.invoke(Method.java:564)
at org.testng.internal.MethodInvocationHelper.invokeMethod(MethodInvocationHelper.java:124)
at org.testng.internal.MethodInvocationHelper.invokeMethodConsideringTimeout(MethodInvocationHelper.java:59)
at org.testng.internal.Invoker.invokeConfigurationMethod(Invoker.java:458)
at org.testng.internal.Invoker.invokeConfigurations(Invoker.java:222)
at org.testng.internal.Invoker.invokeConfigurations(Invoker.java:142)
at org.testng.internal.TestMethodWorker.invokeBeforeClassMethods(TestMethodWorker.java:168)
at org.testng.internal.TestMethodWorker.run(TestMethodWorker.java:105)
at org.testng.TestRunner.privateRun(TestRunner.java:648)
at org.testng.TestRunner.run(TestRunner.java:505)
at org.testng.SuiteRunner.runTest(SuiteRunner.java:455)
at org.testng.SuiteRunner.runSequentially(SuiteRunner.java:450)
at org.testng.SuiteRunner.privateRun(SuiteRunner.java:415)
at org.testng.SuiteRunner.run(SuiteRunner.java:364)
at org.testng.SuiteRunnerWorker.runSuite(SuiteRunnerWorker.java:52)
at org.testng.SuiteRunnerWorker.run(SuiteRunnerWorker.java:84)
at org.testng.TestNG.runSuitesSequentially(TestNG.java:1208)
at org.testng.TestNG.runSuitesLocally(TestNG.java:1137)
at org.testng.TestNG.runSuites(TestNG.java:1049)
at org.testng.TestNG.run(TestNG.java:1017)
at org.testng.remote.AbstractRemoteTestNG.run(AbstractRemoteTestNG.java:115)
at org.testng.remote.RemoteTestNG.initAndRun(RemoteTestNG.java:251)
at org.testng.remote.RemoteTestNG.main(RemoteTestNG.java:77)
Caused by: groovy.json.JsonException: Lexing failed on line: 1, column: 1, while reading '<', no possible valid JSON value or punctuation could be recognized.
at groovy.json.JsonLexer.nextToken(JsonLexer.java:83)
at groovy.json.JsonLexer$nextToken.call(Unknown Source)
at org.codehaus.groovy.runtime.callsite.CallSiteArray.defaultCall(CallSiteArray.java:48)
at org.codehaus.groovy.runtime.callsite.AbstractCallSite.call(AbstractCallSite.java:113)
at org.codehaus.groovy.runtime.callsite.AbstractCallSite.call(AbstractCallSite.java:117)
at io.restassured.internal.path.json.ConfigurableJsonSlurper.parse(ConfigurableJsonSlurper.groovy:97)
at io.restassured.internal.path.json.ConfigurableJsonSlurper$parse.callCurrent(Unknown Source)
at org.codehaus.groovy.runtime.callsite.CallSiteArray.defaultCallCurrent(CallSiteArray.java:52)
at org.codehaus.groovy.runtime.callsite.AbstractCallSite.callCurrent(AbstractCallSite.java:154)
at org.codehaus.groovy.runtime.callsite.AbstractCallSite.callCurrent(AbstractCallSite.java:166)
at io.restassured.internal.path.json.ConfigurableJsonSlurper.parseText(ConfigurableJsonSlurper.groovy:83)
at io.restassured.path.json.JsonPath$4$1.method(JsonPath.java:893)
at io.restassured.path.json.JsonPath$ExceptionCatcher.invoke(JsonPath.java:928)
... 30 more
]]>
            </full-stacktrace>
          </exception> <!-- io.restassured.path.json.exception.JsonPathException -->
          <reporter-output>
          </reporter-output>
        </test-method> <!-- checkstatusLine -->
        <test-method is-config="true" signature="tearDown()[pri:0, instance:com.employeeapi.testCases.TC005_Delete_Employee_Record@11fc564b]" started-at="2021-06-16T09:13:45Z" name="tearDown" finished-at="2021-06-16T09:13:45Z" duration-ms="0" status="SKIP">
          <reporter-output>
          </reporter-output>
        </test-method> <!-- tearDown -->
      </class> <!-- com.employeeapi.testCases.TC005_Delete_Employee_Record -->
      <class name="com.employeeapi.testCases.TC001_Get_All_Employees">
        <test-method is-config="true" signature="setup()[pri:0, instance:com.employeeapi.testCases.TC001_Get_All_Employees@2118cddf]" started-at="2021-06-16T09:13:23Z" name="setup" finished-at="2021-06-16T09:13:23Z" duration-ms="29" status="PASS">
          <reporter-output>
          </reporter-output>
        </test-method> <!-- setup -->
        <test-method is-config="true" signature="getAllEmployees()[pri:0, instance:com.employeeapi.testCases.TC001_Get_All_Employees@2118cddf]" started-at="2021-06-16T09:13:23Z" name="getAllEmployees" finished-at="2021-06-16T09:13:25Z" duration-ms="2291" status="PASS">
          <reporter-output>
          </reporter-output>
        </test-method> <!-- getAllEmployees -->
        <test-method signature="checkContentLenght()[pri:0, instance:com.employeeapi.testCases.TC001_Get_All_Employees@2118cddf]" started-at="2021-06-16T09:13:25Z" name="checkContentLenght" finished-at="2021-06-16T09:13:25Z" duration-ms="6" status="PASS">
          <reporter-output>
          </reporter-output>
        </test-method> <!-- checkContentLenght -->
        <test-method signature="checkContentType()[pri:0, instance:com.employeeapi.testCases.TC001_Get_All_Employees@2118cddf]" started-at="2021-06-16T09:13:25Z" name="checkContentType" finished-at="2021-06-16T09:13:25Z" duration-ms="2" status="FAIL">
          <exception class="java.lang.AssertionError">
            <message>
              <![CDATA[expected [text/html; charset=UTF-8] but found [application/json]]]>
            </message>
            <full-stacktrace>
              <![CDATA[java.lang.AssertionError: expected [text/html; charset=UTF-8] but found [application/json]
at org.testng.Assert.fail(Assert.java:96)
at org.testng.Assert.failNotEquals(Assert.java:776)
at org.testng.Assert.assertEqualsImpl(Assert.java:137)
at org.testng.Assert.assertEquals(Assert.java:118)
at org.testng.Assert.assertEquals(Assert.java:453)
at org.testng.Assert.assertEquals(Assert.java:463)
at com.employeeapi.testCases.TC001_Get_All_Employees.checkContentType(TC001_Get_All_Employees.java:103)
at java.base/jdk.internal.reflect.NativeMethodAccessorImpl.invoke0(Native Method)
at java.base/jdk.internal.reflect.NativeMethodAccessorImpl.invoke(NativeMethodAccessorImpl.java:64)
at java.base/jdk.internal.reflect.DelegatingMethodAccessorImpl.invoke(DelegatingMethodAccessorImpl.java:43)
at java.base/java.lang.reflect.Method.invoke(Method.java:564)
at org.testng.internal.MethodInvocationHelper.invokeMethod(MethodInvocationHelper.java:124)
at org.testng.internal.Invoker.invokeMethod(Invoker.java:583)
at org.testng.internal.Invoker.invokeTestMethod(Invoker.java:719)
at org.testng.internal.Invoker.invokeTestMethods(Invoker.java:989)
at org.testng.internal.TestMethodWorker.invokeTestMethods(TestMethodWorker.java:125)
at org.testng.internal.TestMethodWorker.run(TestMethodWorker.java:109)
at org.testng.TestRunner.privateRun(TestRunner.java:648)
at org.testng.TestRunner.run(TestRunner.java:505)
at org.testng.SuiteRunner.runTest(SuiteRunner.java:455)
at org.testng.SuiteRunner.runSequentially(SuiteRunner.java:450)
at org.testng.SuiteRunner.privateRun(SuiteRunner.java:415)
at org.testng.SuiteRunner.run(SuiteRunner.java:364)
at org.testng.SuiteRunnerWorker.runSuite(SuiteRunnerWorker.java:52)
at org.testng.SuiteRunnerWorker.run(SuiteRunnerWorker.java:84)
at org.testng.TestNG.runSuitesSequentially(TestNG.java:1208)
at org.testng.TestNG.runSuitesLocally(TestNG.java:1137)
at org.testng.TestNG.runSuites(TestNG.java:1049)
at org.testng.TestNG.run(TestNG.java:1017)
at org.testng.remote.AbstractRemoteTestNG.run(AbstractRemoteTestNG.java:115)
at org.testng.remote.RemoteTestNG.initAndRun(RemoteTestNG.java:251)
at org.testng.remote.RemoteTestNG.main(RemoteTestNG.java:77)
]]>
            </full-stacktrace>
          </exception> <!-- java.lang.AssertionError -->
          <reporter-output>
          </reporter-output>
        </test-method> <!-- checkContentType -->
        <test-method signature="checkCookies()[pri:0, instance:com.employeeapi.testCases.TC001_Get_All_Employees@2118cddf]" started-at="2021-06-16T09:13:25Z" name="checkCookies" finished-at="2021-06-16T09:13:25Z" duration-ms="2" status="PASS">
          <reporter-output>
          </reporter-output>
        </test-method> <!-- checkCookies -->
        <test-method signature="checkResponseTime()[pri:0, instance:com.employeeapi.testCases.TC001_Get_All_Employees@2118cddf]" started-at="2021-06-16T09:13:25Z" name="checkResponseTime" finished-at="2021-06-16T09:13:25Z" duration-ms="2" status="PASS">
          <reporter-output>
          </reporter-output>
        </test-method> <!-- checkResponseTime -->
        <test-method signature="checkResposeBody()[pri:0, instance:com.employeeapi.testCases.TC001_Get_All_Employees@2118cddf]" started-at="2021-06-16T09:13:25Z" name="checkResposeBody" finished-at="2021-06-16T09:13:25Z" duration-ms="31" status="PASS">
          <reporter-output>
          </reporter-output>
        </test-method> <!-- checkResposeBody -->
        <test-method signature="checkStatusCode()[pri:0, instance:com.employeeapi.testCases.TC001_Get_All_Employees@2118cddf]" started-at="2021-06-16T09:13:25Z" name="checkStatusCode" finished-at="2021-06-16T09:13:25Z" duration-ms="2" status="PASS">
          <reporter-output>
          </reporter-output>
        </test-method> <!-- checkStatusCode -->
        <test-method signature="checkcontentEncoding()[pri:0, instance:com.employeeapi.testCases.TC001_Get_All_Employees@2118cddf]" started-at="2021-06-16T09:13:25Z" name="checkcontentEncoding" finished-at="2021-06-16T09:13:25Z" duration-ms="2" status="PASS">
          <reporter-output>
          </reporter-output>
        </test-method> <!-- checkcontentEncoding -->
        <test-method signature="checkserverType()[pri:0, instance:com.employeeapi.testCases.TC001_Get_All_Employees@2118cddf]" started-at="2021-06-16T09:13:25Z" name="checkserverType" finished-at="2021-06-16T09:13:25Z" duration-ms="5" status="FAIL">
          <exception class="java.lang.AssertionError">
            <message>
              <![CDATA[expected [nginx/1.14.1] but found [cloudflare]]]>
            </message>
            <full-stacktrace>
              <![CDATA[java.lang.AssertionError: expected [nginx/1.14.1] but found [cloudflare]
at org.testng.Assert.fail(Assert.java:96)
at org.testng.Assert.failNotEquals(Assert.java:776)
at org.testng.Assert.assertEqualsImpl(Assert.java:137)
at org.testng.Assert.assertEquals(Assert.java:118)
at org.testng.Assert.assertEquals(Assert.java:453)
at org.testng.Assert.assertEquals(Assert.java:463)
at com.employeeapi.testCases.TC001_Get_All_Employees.checkserverType(TC001_Get_All_Employees.java:113)
at java.base/jdk.internal.reflect.NativeMethodAccessorImpl.invoke0(Native Method)
at java.base/jdk.internal.reflect.NativeMethodAccessorImpl.invoke(NativeMethodAccessorImpl.java:64)
at java.base/jdk.internal.reflect.DelegatingMethodAccessorImpl.invoke(DelegatingMethodAccessorImpl.java:43)
at java.base/java.lang.reflect.Method.invoke(Method.java:564)
at org.testng.internal.MethodInvocationHelper.invokeMethod(MethodInvocationHelper.java:124)
at org.testng.internal.Invoker.invokeMethod(Invoker.java:583)
at org.testng.internal.Invoker.invokeTestMethod(Invoker.java:719)
at org.testng.internal.Invoker.invokeTestMethods(Invoker.java:989)
at org.testng.internal.TestMethodWorker.invokeTestMethods(TestMethodWorker.java:125)
at org.testng.internal.TestMethodWorker.run(TestMethodWorker.java:109)
at org.testng.TestRunner.privateRun(TestRunner.java:648)
at org.testng.TestRunner.run(TestRunner.java:505)
at org.testng.SuiteRunner.runTest(SuiteRunner.java:455)
at org.testng.SuiteRunner.runSequentially(SuiteRunner.java:450)
at org.testng.SuiteRunner.privateRun(SuiteRunner.java:415)
at org.testng.SuiteRunner.run(SuiteRunner.java:364)
at org.testng.SuiteRunnerWorker.runSuite(SuiteRunnerWorker.java:52)
at org.testng.SuiteRunnerWorker.run(SuiteRunnerWorker.java:84)
at org.testng.TestNG.runSuitesSequentially(TestNG.java:1208)
at org.testng.TestNG.runSuitesLocally(TestNG.java:1137)
at org.testng.TestNG.runSuites(TestNG.java:1049)
at org.testng.TestNG.run(TestNG.java:1017)
at org.testng.remote.AbstractRemoteTestNG.run(AbstractRemoteTestNG.java:115)
at org.testng.remote.RemoteTestNG.initAndRun(RemoteTestNG.java:251)
at org.testng.remote.RemoteTestNG.main(RemoteTestNG.java:77)
]]>
            </full-stacktrace>
          </exception> <!-- java.lang.AssertionError -->
          <reporter-output>
          </reporter-output>
        </test-method> <!-- checkserverType -->
        <test-method signature="checkstatusLine()[pri:0, instance:com.employeeapi.testCases.TC001_Get_All_Employees@2118cddf]" started-at="2021-06-16T09:13:25Z" name="checkstatusLine" finished-at="2021-06-16T09:13:25Z" duration-ms="1" status="PASS">
          <reporter-output>
          </reporter-output>
        </test-method> <!-- checkstatusLine -->
        <test-method is-config="true" signature="tearDown()[pri:0, instance:com.employeeapi.testCases.TC001_Get_All_Employees@2118cddf]" started-at="2021-06-16T09:13:25Z" name="tearDown" finished-at="2021-06-16T09:13:25Z" duration-ms="0" status="PASS">
          <reporter-output>
          </reporter-output>
        </test-method> <!-- tearDown -->
      </class> <!-- com.employeeapi.testCases.TC001_Get_All_Employees -->
      <class name="com.employeeapi.testCases.TC004_Put_Employee_Record">
        <test-method is-config="true" signature="setup()[pri:0, instance:com.employeeapi.testCases.TC004_Put_Employee_Record@76ed1b7c]" started-at="2021-06-16T09:13:38Z" name="setup" finished-at="2021-06-16T09:13:38Z" duration-ms="7" status="PASS">
          <reporter-output>
          </reporter-output>
        </test-method> <!-- setup -->
        <test-method is-config="true" signature="updateEmployee()[pri:0, instance:com.employeeapi.testCases.TC004_Put_Employee_Record@76ed1b7c]" started-at="2021-06-16T09:13:38Z" name="updateEmployee" finished-at="2021-06-16T09:13:44Z" duration-ms="6110" status="PASS">
          <reporter-output>
          </reporter-output>
        </test-method> <!-- updateEmployee -->
        <test-method signature="checkContentType()[pri:0, instance:com.employeeapi.testCases.TC004_Put_Employee_Record@76ed1b7c]" started-at="2021-06-16T09:13:44Z" name="checkContentType" finished-at="2021-06-16T09:13:44Z" duration-ms="1" status="FAIL">
          <exception class="java.lang.AssertionError">
            <message>
              <![CDATA[expected [text/html; charset=UTF-8] but found [application/json]]]>
            </message>
            <full-stacktrace>
              <![CDATA[java.lang.AssertionError: expected [text/html; charset=UTF-8] but found [application/json]
at org.testng.Assert.fail(Assert.java:96)
at org.testng.Assert.failNotEquals(Assert.java:776)
at org.testng.Assert.assertEqualsImpl(Assert.java:137)
at org.testng.Assert.assertEquals(Assert.java:118)
at org.testng.Assert.assertEquals(Assert.java:453)
at org.testng.Assert.assertEquals(Assert.java:463)
at com.employeeapi.testCases.TC004_Put_Employee_Record.checkContentType(TC004_Put_Employee_Record.java:95)
at java.base/jdk.internal.reflect.NativeMethodAccessorImpl.invoke0(Native Method)
at java.base/jdk.internal.reflect.NativeMethodAccessorImpl.invoke(NativeMethodAccessorImpl.java:64)
at java.base/jdk.internal.reflect.DelegatingMethodAccessorImpl.invoke(DelegatingMethodAccessorImpl.java:43)
at java.base/java.lang.reflect.Method.invoke(Method.java:564)
at org.testng.internal.MethodInvocationHelper.invokeMethod(MethodInvocationHelper.java:124)
at org.testng.internal.Invoker.invokeMethod(Invoker.java:583)
at org.testng.internal.Invoker.invokeTestMethod(Invoker.java:719)
at org.testng.internal.Invoker.invokeTestMethods(Invoker.java:989)
at org.testng.internal.TestMethodWorker.invokeTestMethods(TestMethodWorker.java:125)
at org.testng.internal.TestMethodWorker.run(TestMethodWorker.java:109)
at org.testng.TestRunner.privateRun(TestRunner.java:648)
at org.testng.TestRunner.run(TestRunner.java:505)
at org.testng.SuiteRunner.runTest(SuiteRunner.java:455)
at org.testng.SuiteRunner.runSequentially(SuiteRunner.java:450)
at org.testng.SuiteRunner.privateRun(SuiteRunner.java:415)
at org.testng.SuiteRunner.run(SuiteRunner.java:364)
at org.testng.SuiteRunnerWorker.runSuite(SuiteRunnerWorker.java:52)
at org.testng.SuiteRunnerWorker.run(SuiteRunnerWorker.java:84)
at org.testng.TestNG.runSuitesSequentially(TestNG.java:1208)
at org.testng.TestNG.runSuitesLocally(TestNG.java:1137)
at org.testng.TestNG.runSuites(TestNG.java:1049)
at org.testng.TestNG.run(TestNG.java:1017)
at org.testng.remote.AbstractRemoteTestNG.run(AbstractRemoteTestNG.java:115)
at org.testng.remote.RemoteTestNG.initAndRun(RemoteTestNG.java:251)
at org.testng.remote.RemoteTestNG.main(RemoteTestNG.java:77)
]]>
            </full-stacktrace>
          </exception> <!-- java.lang.AssertionError -->
          <reporter-output>
          </reporter-output>
        </test-method> <!-- checkContentType -->
        <test-method signature="checkResposeBody()[pri:0, instance:com.employeeapi.testCases.TC004_Put_Employee_Record@76ed1b7c]" started-at="2021-06-16T09:13:44Z" name="checkResposeBody" finished-at="2021-06-16T09:13:44Z" duration-ms="0" status="PASS">
          <reporter-output>
          </reporter-output>
        </test-method> <!-- checkResposeBody -->
        <test-method signature="checkStatusCode()[pri:0, instance:com.employeeapi.testCases.TC004_Put_Employee_Record@76ed1b7c]" started-at="2021-06-16T09:13:44Z" name="checkStatusCode" finished-at="2021-06-16T09:13:44Z" duration-ms="1" status="PASS">
          <reporter-output>
          </reporter-output>
        </test-method> <!-- checkStatusCode -->
        <test-method signature="checkcontentEncoding()[pri:0, instance:com.employeeapi.testCases.TC004_Put_Employee_Record@76ed1b7c]" started-at="2021-06-16T09:13:44Z" name="checkcontentEncoding" finished-at="2021-06-16T09:13:44Z" duration-ms="1" status="PASS">
          <reporter-output>
          </reporter-output>
        </test-method> <!-- checkcontentEncoding -->
        <test-method signature="checkserverType()[pri:0, instance:com.employeeapi.testCases.TC004_Put_Employee_Record@76ed1b7c]" started-at="2021-06-16T09:13:44Z" name="checkserverType" finished-at="2021-06-16T09:13:44Z" duration-ms="1" status="FAIL">
          <exception class="java.lang.AssertionError">
            <message>
              <![CDATA[expected [nginx/1.14.1] but found [cloudflare]]]>
            </message>
            <full-stacktrace>
              <![CDATA[java.lang.AssertionError: expected [nginx/1.14.1] but found [cloudflare]
at org.testng.Assert.fail(Assert.java:96)
at org.testng.Assert.failNotEquals(Assert.java:776)
at org.testng.Assert.assertEqualsImpl(Assert.java:137)
at org.testng.Assert.assertEquals(Assert.java:118)
at org.testng.Assert.assertEquals(Assert.java:453)
at org.testng.Assert.assertEquals(Assert.java:463)
at com.employeeapi.testCases.TC004_Put_Employee_Record.checkserverType(TC004_Put_Employee_Record.java:102)
at java.base/jdk.internal.reflect.NativeMethodAccessorImpl.invoke0(Native Method)
at java.base/jdk.internal.reflect.NativeMethodAccessorImpl.invoke(NativeMethodAccessorImpl.java:64)
at java.base/jdk.internal.reflect.DelegatingMethodAccessorImpl.invoke(DelegatingMethodAccessorImpl.java:43)
at java.base/java.lang.reflect.Method.invoke(Method.java:564)
at org.testng.internal.MethodInvocationHelper.invokeMethod(MethodInvocationHelper.java:124)
at org.testng.internal.Invoker.invokeMethod(Invoker.java:583)
at org.testng.internal.Invoker.invokeTestMethod(Invoker.java:719)
at org.testng.internal.Invoker.invokeTestMethods(Invoker.java:989)
at org.testng.internal.TestMethodWorker.invokeTestMethods(TestMethodWorker.java:125)
at org.testng.internal.TestMethodWorker.run(TestMethodWorker.java:109)
at org.testng.TestRunner.privateRun(TestRunner.java:648)
at org.testng.TestRunner.run(TestRunner.java:505)
at org.testng.SuiteRunner.runTest(SuiteRunner.java:455)
at org.testng.SuiteRunner.runSequentially(SuiteRunner.java:450)
at org.testng.SuiteRunner.privateRun(SuiteRunner.java:415)
at org.testng.SuiteRunner.run(SuiteRunner.java:364)
at org.testng.SuiteRunnerWorker.runSuite(SuiteRunnerWorker.java:52)
at org.testng.SuiteRunnerWorker.run(SuiteRunnerWorker.java:84)
at org.testng.TestNG.runSuitesSequentially(TestNG.java:1208)
at org.testng.TestNG.runSuitesLocally(TestNG.java:1137)
at org.testng.TestNG.runSuites(TestNG.java:1049)
at org.testng.TestNG.run(TestNG.java:1017)
at org.testng.remote.AbstractRemoteTestNG.run(AbstractRemoteTestNG.java:115)
at org.testng.remote.RemoteTestNG.initAndRun(RemoteTestNG.java:251)
at org.testng.remote.RemoteTestNG.main(RemoteTestNG.java:77)
]]>
            </full-stacktrace>
          </exception> <!-- java.lang.AssertionError -->
          <reporter-output>
          </reporter-output>
        </test-method> <!-- checkserverType -->
        <test-method signature="checkstatusLine()[pri:0, instance:com.employeeapi.testCases.TC004_Put_Employee_Record@76ed1b7c]" started-at="2021-06-16T09:13:44Z" name="checkstatusLine" finished-at="2021-06-16T09:13:44Z" duration-ms="1" status="PASS">
          <reporter-output>
          </reporter-output>
        </test-method> <!-- checkstatusLine -->
        <test-method is-config="true" signature="tearDown()[pri:0, instance:com.employeeapi.testCases.TC004_Put_Employee_Record@76ed1b7c]" started-at="2021-06-16T09:13:44Z" name="tearDown" finished-at="2021-06-16T09:13:44Z" duration-ms="1" status="PASS">
          <reporter-output>
          </reporter-output>
        </test-method> <!-- tearDown -->
      </class> <!-- com.employeeapi.testCases.TC004_Put_Employee_Record -->
      <class name="com.employeeapi.testCases.TC002_Get_Single_Employee_Record">
        <test-method is-config="true" signature="setup()[pri:0, instance:com.employeeapi.testCases.TC002_Get_Single_Employee_Record@17a7f733]" started-at="2021-06-16T09:13:25Z" name="setup" finished-at="2021-06-16T09:13:25Z" duration-ms="3" status="PASS">
          <reporter-output>
          </reporter-output>
        </test-method> <!-- setup -->
        <test-method is-config="true" signature="getEmployeeData()[pri:0, instance:com.employeeapi.testCases.TC002_Get_Single_Employee_Record@17a7f733]" started-at="2021-06-16T09:13:25Z" name="getEmployeeData" finished-at="2021-06-16T09:13:31Z" duration-ms="6098" status="PASS">
          <reporter-output>
          </reporter-output>
        </test-method> <!-- getEmployeeData -->
        <test-method signature="checkContentLenght()[pri:0, instance:com.employeeapi.testCases.TC002_Get_Single_Employee_Record@17a7f733]" started-at="2021-06-16T09:13:31Z" name="checkContentLenght" finished-at="2021-06-16T09:13:31Z" duration-ms="2" status="FAIL">
          <exception class="java.lang.NumberFormatException">
            <message>
              <![CDATA[null]]>
            </message>
            <full-stacktrace>
              <![CDATA[java.lang.NumberFormatException: null
at java.base/java.lang.Integer.parseInt(Integer.java:614)
at java.base/java.lang.Integer.parseInt(Integer.java:770)
at com.employeeapi.testCases.TC002_Get_Single_Employee_Record.checkContentLenght(TC002_Get_Single_Employee_Record.java:93)
at java.base/jdk.internal.reflect.NativeMethodAccessorImpl.invoke0(Native Method)
at java.base/jdk.internal.reflect.NativeMethodAccessorImpl.invoke(NativeMethodAccessorImpl.java:64)
at java.base/jdk.internal.reflect.DelegatingMethodAccessorImpl.invoke(DelegatingMethodAccessorImpl.java:43)
at java.base/java.lang.reflect.Method.invoke(Method.java:564)
at org.testng.internal.MethodInvocationHelper.invokeMethod(MethodInvocationHelper.java:124)
at org.testng.internal.Invoker.invokeMethod(Invoker.java:583)
at org.testng.internal.Invoker.invokeTestMethod(Invoker.java:719)
at org.testng.internal.Invoker.invokeTestMethods(Invoker.java:989)
at org.testng.internal.TestMethodWorker.invokeTestMethods(TestMethodWorker.java:125)
at org.testng.internal.TestMethodWorker.run(TestMethodWorker.java:109)
at org.testng.TestRunner.privateRun(TestRunner.java:648)
at org.testng.TestRunner.run(TestRunner.java:505)
at org.testng.SuiteRunner.runTest(SuiteRunner.java:455)
at org.testng.SuiteRunner.runSequentially(SuiteRunner.java:450)
at org.testng.SuiteRunner.privateRun(SuiteRunner.java:415)
at org.testng.SuiteRunner.run(SuiteRunner.java:364)
at org.testng.SuiteRunnerWorker.runSuite(SuiteRunnerWorker.java:52)
at org.testng.SuiteRunnerWorker.run(SuiteRunnerWorker.java:84)
at org.testng.TestNG.runSuitesSequentially(TestNG.java:1208)
at org.testng.TestNG.runSuitesLocally(TestNG.java:1137)
at org.testng.TestNG.runSuites(TestNG.java:1049)
at org.testng.TestNG.run(TestNG.java:1017)
at org.testng.remote.AbstractRemoteTestNG.run(AbstractRemoteTestNG.java:115)
at org.testng.remote.RemoteTestNG.initAndRun(RemoteTestNG.java:251)
at org.testng.remote.RemoteTestNG.main(RemoteTestNG.java:77)
]]>
            </full-stacktrace>
          </exception> <!-- java.lang.NumberFormatException -->
          <reporter-output>
          </reporter-output>
        </test-method> <!-- checkContentLenght -->
        <test-method signature="checkContentType()[pri:0, instance:com.employeeapi.testCases.TC002_Get_Single_Employee_Record@17a7f733]" started-at="2021-06-16T09:13:31Z" name="checkContentType" finished-at="2021-06-16T09:13:31Z" duration-ms="0" status="FAIL">
          <exception class="java.lang.AssertionError">
            <message>
              <![CDATA[expected [text/html; charset=UTF-8] but found [application/json]]]>
            </message>
            <full-stacktrace>
              <![CDATA[java.lang.AssertionError: expected [text/html; charset=UTF-8] but found [application/json]
at org.testng.Assert.fail(Assert.java:96)
at org.testng.Assert.failNotEquals(Assert.java:776)
at org.testng.Assert.assertEqualsImpl(Assert.java:137)
at org.testng.Assert.assertEquals(Assert.java:118)
at org.testng.Assert.assertEquals(Assert.java:453)
at org.testng.Assert.assertEquals(Assert.java:463)
at com.employeeapi.testCases.TC002_Get_Single_Employee_Record.checkContentType(TC002_Get_Single_Employee_Record.java:79)
at java.base/jdk.internal.reflect.NativeMethodAccessorImpl.invoke0(Native Method)
at java.base/jdk.internal.reflect.NativeMethodAccessorImpl.invoke(NativeMethodAccessorImpl.java:64)
at java.base/jdk.internal.reflect.DelegatingMethodAccessorImpl.invoke(DelegatingMethodAccessorImpl.java:43)
at java.base/java.lang.reflect.Method.invoke(Method.java:564)
at org.testng.internal.MethodInvocationHelper.invokeMethod(MethodInvocationHelper.java:124)
at org.testng.internal.Invoker.invokeMethod(Invoker.java:583)
at org.testng.internal.Invoker.invokeTestMethod(Invoker.java:719)
at org.testng.internal.Invoker.invokeTestMethods(Invoker.java:989)
at org.testng.internal.TestMethodWorker.invokeTestMethods(TestMethodWorker.java:125)
at org.testng.internal.TestMethodWorker.run(TestMethodWorker.java:109)
at org.testng.TestRunner.privateRun(TestRunner.java:648)
at org.testng.TestRunner.run(TestRunner.java:505)
at org.testng.SuiteRunner.runTest(SuiteRunner.java:455)
at org.testng.SuiteRunner.runSequentially(SuiteRunner.java:450)
at org.testng.SuiteRunner.privateRun(SuiteRunner.java:415)
at org.testng.SuiteRunner.run(SuiteRunner.java:364)
at org.testng.SuiteRunnerWorker.runSuite(SuiteRunnerWorker.java:52)
at org.testng.SuiteRunnerWorker.run(SuiteRunnerWorker.java:84)
at org.testng.TestNG.runSuitesSequentially(TestNG.java:1208)
at org.testng.TestNG.runSuitesLocally(TestNG.java:1137)
at org.testng.TestNG.runSuites(TestNG.java:1049)
at org.testng.TestNG.run(TestNG.java:1017)
at org.testng.remote.AbstractRemoteTestNG.run(AbstractRemoteTestNG.java:115)
at org.testng.remote.RemoteTestNG.initAndRun(RemoteTestNG.java:251)
at org.testng.remote.RemoteTestNG.main(RemoteTestNG.java:77)
]]>
            </full-stacktrace>
          </exception> <!-- java.lang.AssertionError -->
          <reporter-output>
          </reporter-output>
        </test-method> <!-- checkContentType -->
        <test-method signature="checkResponseTime()[pri:0, instance:com.employeeapi.testCases.TC002_Get_Single_Employee_Record@17a7f733]" started-at="2021-06-16T09:13:31Z" name="checkResponseTime" finished-at="2021-06-16T09:13:31Z" duration-ms="0" status="PASS">
          <reporter-output>
          </reporter-output>
        </test-method> <!-- checkResponseTime -->
        <test-method signature="checkResposeBody()[pri:0, instance:com.employeeapi.testCases.TC002_Get_Single_Employee_Record@17a7f733]" started-at="2021-06-16T09:13:31Z" name="checkResposeBody" finished-at="2021-06-16T09:13:31Z" duration-ms="0" status="FAIL">
          <exception class="java.lang.AssertionError">
            <message>
              <![CDATA[expected [true] but found [false]]]>
            </message>
            <full-stacktrace>
              <![CDATA[java.lang.AssertionError: expected [true] but found [false]
at org.testng.Assert.fail(Assert.java:96)
at org.testng.Assert.failNotEquals(Assert.java:776)
at org.testng.Assert.assertEqualsImpl(Assert.java:137)
at org.testng.Assert.assertEquals(Assert.java:118)
at org.testng.Assert.assertEquals(Assert.java:568)
at org.testng.Assert.assertEquals(Assert.java:578)
at com.employeeapi.testCases.TC002_Get_Single_Employee_Record.checkResposeBody(TC002_Get_Single_Employee_Record.java:49)
at java.base/jdk.internal.reflect.NativeMethodAccessorImpl.invoke0(Native Method)
at java.base/jdk.internal.reflect.NativeMethodAccessorImpl.invoke(NativeMethodAccessorImpl.java:64)
at java.base/jdk.internal.reflect.DelegatingMethodAccessorImpl.invoke(DelegatingMethodAccessorImpl.java:43)
at java.base/java.lang.reflect.Method.invoke(Method.java:564)
at org.testng.internal.MethodInvocationHelper.invokeMethod(MethodInvocationHelper.java:124)
at org.testng.internal.Invoker.invokeMethod(Invoker.java:583)
at org.testng.internal.Invoker.invokeTestMethod(Invoker.java:719)
at org.testng.internal.Invoker.invokeTestMethods(Invoker.java:989)
at org.testng.internal.TestMethodWorker.invokeTestMethods(TestMethodWorker.java:125)
at org.testng.internal.TestMethodWorker.run(TestMethodWorker.java:109)
at org.testng.TestRunner.privateRun(TestRunner.java:648)
at org.testng.TestRunner.run(TestRunner.java:505)
at org.testng.SuiteRunner.runTest(SuiteRunner.java:455)
at org.testng.SuiteRunner.runSequentially(SuiteRunner.java:450)
at org.testng.SuiteRunner.privateRun(SuiteRunner.java:415)
at org.testng.SuiteRunner.run(SuiteRunner.java:364)
at org.testng.SuiteRunnerWorker.runSuite(SuiteRunnerWorker.java:52)
at org.testng.SuiteRunnerWorker.run(SuiteRunnerWorker.java:84)
at org.testng.TestNG.runSuitesSequentially(TestNG.java:1208)
at org.testng.TestNG.runSuitesLocally(TestNG.java:1137)
at org.testng.TestNG.runSuites(TestNG.java:1049)
at org.testng.TestNG.run(TestNG.java:1017)
at org.testng.remote.AbstractRemoteTestNG.run(AbstractRemoteTestNG.java:115)
at org.testng.remote.RemoteTestNG.initAndRun(RemoteTestNG.java:251)
at org.testng.remote.RemoteTestNG.main(RemoteTestNG.java:77)
]]>
            </full-stacktrace>
          </exception> <!-- java.lang.AssertionError -->
          <reporter-output>
          </reporter-output>
        </test-method> <!-- checkResposeBody -->
        <test-method signature="checkStatusCode()[pri:0, instance:com.employeeapi.testCases.TC002_Get_Single_Employee_Record@17a7f733]" started-at="2021-06-16T09:13:31Z" name="checkStatusCode" finished-at="2021-06-16T09:13:31Z" duration-ms="1" status="PASS">
          <reporter-output>
          </reporter-output>
        </test-method> <!-- checkStatusCode -->
        <test-method signature="checkserverType()[pri:0, instance:com.employeeapi.testCases.TC002_Get_Single_Employee_Record@17a7f733]" started-at="2021-06-16T09:13:31Z" name="checkserverType" finished-at="2021-06-16T09:13:31Z" duration-ms="1" status="FAIL">
          <exception class="java.lang.AssertionError">
            <message>
              <![CDATA[expected [nginx/1.14.1] but found [cloudflare]]]>
            </message>
            <full-stacktrace>
              <![CDATA[java.lang.AssertionError: expected [nginx/1.14.1] but found [cloudflare]
at org.testng.Assert.fail(Assert.java:96)
at org.testng.Assert.failNotEquals(Assert.java:776)
at org.testng.Assert.assertEqualsImpl(Assert.java:137)
at org.testng.Assert.assertEquals(Assert.java:118)
at org.testng.Assert.assertEquals(Assert.java:453)
at org.testng.Assert.assertEquals(Assert.java:463)
at com.employeeapi.testCases.TC002_Get_Single_Employee_Record.checkserverType(TC002_Get_Single_Employee_Record.java:86)
at java.base/jdk.internal.reflect.NativeMethodAccessorImpl.invoke0(Native Method)
at java.base/jdk.internal.reflect.NativeMethodAccessorImpl.invoke(NativeMethodAccessorImpl.java:64)
at java.base/jdk.internal.reflect.DelegatingMethodAccessorImpl.invoke(DelegatingMethodAccessorImpl.java:43)
at java.base/java.lang.reflect.Method.invoke(Method.java:564)
at org.testng.internal.MethodInvocationHelper.invokeMethod(MethodInvocationHelper.java:124)
at org.testng.internal.Invoker.invokeMethod(Invoker.java:583)
at org.testng.internal.Invoker.invokeTestMethod(Invoker.java:719)
at org.testng.internal.Invoker.invokeTestMethods(Invoker.java:989)
at org.testng.internal.TestMethodWorker.invokeTestMethods(TestMethodWorker.java:125)
at org.testng.internal.TestMethodWorker.run(TestMethodWorker.java:109)
at org.testng.TestRunner.privateRun(TestRunner.java:648)
at org.testng.TestRunner.run(TestRunner.java:505)
at org.testng.SuiteRunner.runTest(SuiteRunner.java:455)
at org.testng.SuiteRunner.runSequentially(SuiteRunner.java:450)
at org.testng.SuiteRunner.privateRun(SuiteRunner.java:415)
at org.testng.SuiteRunner.run(SuiteRunner.java:364)
at org.testng.SuiteRunnerWorker.runSuite(SuiteRunnerWorker.java:52)
at org.testng.SuiteRunnerWorker.run(SuiteRunnerWorker.java:84)
at org.testng.TestNG.runSuitesSequentially(TestNG.java:1208)
at org.testng.TestNG.runSuitesLocally(TestNG.java:1137)
at org.testng.TestNG.runSuites(TestNG.java:1049)
at org.testng.TestNG.run(TestNG.java:1017)
at org.testng.remote.AbstractRemoteTestNG.run(AbstractRemoteTestNG.java:115)
at org.testng.remote.RemoteTestNG.initAndRun(RemoteTestNG.java:251)
at org.testng.remote.RemoteTestNG.main(RemoteTestNG.java:77)
]]>
            </full-stacktrace>
          </exception> <!-- java.lang.AssertionError -->
          <reporter-output>
          </reporter-output>
        </test-method> <!-- checkserverType -->
        <test-method signature="checkstatusLine()[pri:0, instance:com.employeeapi.testCases.TC002_Get_Single_Employee_Record@17a7f733]" started-at="2021-06-16T09:13:31Z" name="checkstatusLine" finished-at="2021-06-16T09:13:31Z" duration-ms="1" status="PASS">
          <reporter-output>
          </reporter-output>
        </test-method> <!-- checkstatusLine -->
        <test-method is-config="true" signature="tearDown()[pri:0, instance:com.employeeapi.testCases.TC002_Get_Single_Employee_Record@17a7f733]" started-at="2021-06-16T09:13:31Z" name="tearDown" finished-at="2021-06-16T09:13:31Z" duration-ms="1" status="PASS">
          <reporter-output>
          </reporter-output>
        </test-method> <!-- tearDown -->
      </class> <!-- com.employeeapi.testCases.TC002_Get_Single_Employee_Record -->
    </test> <!-- EmployeesRestAPITest -->
  </suite> <!-- EmployeesRestAPISuite -->
</testng-results>
